experimentalAnalysis/hash_rb_Experimental/test-f1-3.txt
200000
buy 67
buy 62
buy 74
buy 58
buy 81
buy 72
buy 91
buy 82
buy 70
buy 87
buy 95
buy 77
buy 74
buy 90
buy 83
buy 76
buy 98
buy 92
buy 53
buy 91
buy 87
buy 78
buy 82
buy 61
buy 94
buy 60
buy 77
buy 78
buy 100
buy 91
buy 87
buy 58
buy 71
buy 79
buy 51
buy 66
buy 64
buy 73
buy 87
buy 83
buy 73
buy 90
buy 66
buy 62
buy 59
buy 99
buy 77
buy 100
buy 65
buy 91
buy 70
buy 91
buy 63
buy 79
buy 96
buy 91
buy 80
buy 96
buy 61
buy 76
buy 61
buy 50
buy 55
buy 67
buy 69
buy 71
buy 58
buy 67
buy 56
buy 55
buy 93
buy 82
buy 53
buy 88
buy 61
buy 63
buy 54
buy 76
buy 69
buy 69
buy 92
buy 83
buy 75
buy 97
buy 81
buy 54
buy 51
buy 65
buy 82
buy 81
buy 65
buy 60
buy 71
buy 100
buy 85
buy 80
buy 52
buy 61
buy 99
buy 62
buy 71
buy 61
buy 82
buy 53
buy 59
buy 50
buy 78
buy 97
buy 75
buy 68
buy 85
buy 50
buy 100
buy 85
buy 86
buy 64
buy 87
buy 50
buy 53
buy 79
buy 66
buy 84
buy 96
buy 73
buy 98
buy 60
buy 58
buy 64
buy 85
buy 74
buy 82
buy 81
buy 86
buy 62
buy 92
buy 70
buy 98
buy 64
buy 95
buy 56
buy 73
buy 66
buy 64
buy 66
buy 53
buy 57
buy 100
buy 56
buy 66
buy 77
buy 55
buy 67
buy 97
buy 92
buy 74
buy 97
buy 93
buy 97
buy 70
buy 57
buy 51
buy 67
buy 86
buy 73
buy 88
buy 55
buy 50
buy 77
buy 94
buy 82
buy 99
buy 86
buy 52
buy 74
buy 71
buy 63
buy 65
buy 68
buy 51
buy 92
buy 94
buy 79
buy 53
buy 99
buy 68
buy 93
buy 86
buy 74
buy 69
buy 76
buy 67
buy 71
buy 60
buy 92
buy 92
buy 55
buy 83
buy 63
buy 55
buy 65
buy 69
buy 69
buy 50
buy 82
buy 97
buy 67
buy 87
buy 84
buy 70
buy 57
buy 98
buy 64
buy 96
buy 89
buy 92
buy 54
buy 82
buy 60
buy 60
buy 94
buy 94
buy 89
buy 75
buy 98
buy 82
buy 91
buy 95
buy 50
buy 88
buy 88
buy 89
buy 71
buy 93
buy 96
buy 84
buy 96
buy 98
buy 99
buy 52
buy 93
buy 74
buy 79
buy 56
buy 72
buy 71
buy 52
buy 85
buy 94
buy 64
buy 74
buy 80
buy 59
buy 92
buy 67
buy 86
buy 96
buy 85
buy 53
buy 73
buy 69
buy 92
buy 57
buy 80
buy 62
buy 77
buy 69
buy 55
buy 79
buy 84
buy 68
buy 98
buy 77
buy 58
buy 55
buy 64
buy 97
buy 54
buy 100
buy 72
buy 69
buy 64
buy 92
buy 82
buy 86
buy 60
buy 89
buy 75
buy 52
buy 77
buy 56
buy 65
buy 52
buy 63
buy 69
buy 55
buy 79
buy 72
buy 60
buy 60
buy 85
buy 55
buy 75
buy 75
buy 61
buy 73
buy 70
buy 91
buy 90
buy 71
buy 96
buy 89
buy 78
buy 51
buy 84
buy 80
buy 53
buy 58
buy 64
buy 52
buy 70
buy 95
buy 65
buy 64
buy 70
buy 74
buy 50
buy 95
buy 58
buy 70
buy 97
buy 72
buy 55
buy 51
buy 84
buy 85
buy 98
buy 68
buy 54
buy 99
buy 75
buy 75
buy 98
buy 62
buy 78
buy 51
buy 75
buy 86
buy 80
buy 63
buy 59
buy 85
buy 79
buy 73
buy 72
buy 77
buy 91
buy 99
buy 50
buy 65
buy 95
buy 98
buy 63
buy 70
buy 81
buy 92
buy 87
buy 78
buy 54
buy 84
buy 86
buy 54
buy 65
buy 75
buy 76
buy 60
buy 55
buy 59
buy 78
buy 57
buy 77
buy 86
buy 97
buy 97
buy 100
buy 79
buy 84
buy 79
buy 96
buy 79
buy 79
buy 93
buy 74
buy 59
buy 95
buy 97
buy 86
buy 98
buy 62
buy 87
buy 77
buy 95
buy 92
buy 55
buy 74
buy 78
buy 54
buy 98
buy 57
buy 84
buy 85
buy 73
buy 71
buy 91
buy 64
buy 68
buy 94
buy 57
buy 64
buy 70
buy 58
buy 62
buy 100
buy 99
buy 57
buy 53
buy 78
buy 67
buy 90
buy 65
buy 51
buy 58
buy 67
buy 63
buy 75
buy 100
buy 71
buy 90
buy 67
buy 99
buy 86
buy 52
buy 94
buy 98
buy 75
buy 71
buy 59
buy 80
buy 61
buy 59
buy 62
buy 71
buy 62
buy 62
buy 75
buy 62
buy 51
buy 66
buy 90
buy 59
buy 51
buy 52
buy 64
buy 86
buy 88
buy 79
buy 100
buy 72
buy 98
buy 85
buy 56
buy 96
buy 70
buy 75
buy 53
buy 73
buy 98
buy 57
buy 69
buy 82
buy 98
buy 70
buy 59
buy 53
buy 79
buy 66
buy 99
buy 98
buy 60
buy 84
buy 80
buy 97
buy 91
buy 59
buy 60
buy 70
buy 64
buy 58
buy 98
buy 68
buy 73
buy 82
buy 86
buy 67
buy 73
buy 89
buy 93
buy 71
buy 98
buy 66
buy 80
buy 65
buy 99
buy 72
buy 56
buy 60
buy 60
buy 100
buy 61
buy 52
buy 58
buy 71
buy 62
buy 58
buy 86
buy 86
buy 78
buy 52
buy 88
buy 100
buy 72
buy 56
buy 74
buy 87
buy 50
buy 79
buy 88
buy 76
buy 98
buy 66
buy 79
buy 56
buy 54
buy 92
buy 94
buy 87
buy 53
buy 67
buy 85
buy 65
buy 51
buy 72
buy 92
buy 50
buy 83
buy 98
buy 79
buy 59
buy 93
buy 57
buy 77
buy 53
buy 78
buy 93
buy 70
buy 59
buy 97
buy 61
buy 83
buy 50
buy 51
buy 53
buy 88
buy 50
buy 56
buy 82
buy 63
buy 100
buy 86
buy 92
buy 86
buy 97
buy 73
buy 59
buy 82
buy 75
buy 88
buy 57
buy 99
buy 85
buy 61
buy 73
buy 65
buy 63
buy 95
buy 81
buy 70
buy 82
buy 83
buy 73
buy 83
buy 97
buy 69
buy 53
buy 75
buy 67
buy 71
buy 53
buy 72
buy 64
buy 54
buy 74
buy 81
buy 59
buy 92
buy 75
buy 73
buy 63
buy 61
buy 59
buy 77
buy 63
buy 70
buy 92
buy 96
buy 52
buy 71
buy 70
buy 68
buy 54
buy 82
buy 86
buy 68
buy 77
buy 73
buy 78
buy 70
buy 66
buy 87
buy 55
buy 64
buy 68
buy 78
buy 57
buy 85
buy 52
buy 67
buy 72
buy 66
buy 60
buy 56
buy 86
buy 80
buy 71
buy 94
buy 81
buy 89
buy 90
buy 90
buy 92
buy 68
buy 53
buy 97
buy 94
buy 65
buy 85
buy 50
buy 67
buy 64
buy 90
buy 75
buy 98
buy 86
buy 97
buy 64
buy 83
buy 84
buy 76
buy 51
buy 68
buy 52
buy 88
buy 55
buy 54
buy 80
buy 60
buy 77
buy 66
buy 93
buy 50
buy 54
buy 63
buy 82
buy 62
buy 59
buy 81
buy 84
buy 98
buy 65
buy 97
buy 71
buy 79
buy 96
buy 51
buy 71
buy 79
buy 78
buy 65
buy 92
buy 88
buy 55
buy 100
buy 58
buy 61
buy 87
buy 90
buy 100
buy 56
buy 88
buy 72
buy 56
buy 64
buy 51
buy 70
buy 90
buy 69
buy 97
buy 83
buy 79
buy 95
buy 53
buy 94
buy 62
buy 56
buy 65
buy 62
buy 100
buy 72
buy 94
buy 56
buy 72
buy 97
buy 62
buy 56
buy 75
buy 54
buy 79
buy 80
buy 80
buy 91
buy 50
buy 91
buy 59
buy 92
buy 58
buy 66
buy 91
buy 51
buy 87
buy 91
buy 50
buy 93
buy 55
buy 54
buy 70
buy 59
buy 68
buy 54
buy 71
buy 77
buy 54
buy 71
buy 82
buy 97
buy 70
buy 68
buy 84
buy 98
buy 57
buy 83
buy 50
buy 75
buy 68
buy 84
buy 55
buy 92
buy 74
buy 92
buy 61
buy 54
buy 92
buy 95
buy 86
buy 59
buy 93
buy 66
buy 59
buy 63
buy 84
buy 85
buy 91
buy 73
buy 85
buy 61
buy 90
buy 71
buy 99
buy 93
buy 70
buy 87
buy 75
buy 89
buy 81
buy 100
buy 56
buy 63
buy 93
buy 56
buy 68
buy 85
buy 91
buy 99
buy 60
buy 72
buy 63
buy 97
buy 67
buy 71
buy 100
buy 77
buy 54
buy 64
buy 94
buy 59
buy 88
buy 61
buy 78
buy 78
buy 69
buy 99
buy 97
buy 88
buy 96
buy 85
buy 99
buy 93
buy 84
buy 90
buy 74
buy 88
buy 96
buy 88
buy 61
buy 68
buy 52
buy 64
buy 64
buy 93
buy 82
buy 94
buy 53
buy 100
buy 64
buy 94
buy 54
buy 83
buy 92
buy 94
buy 64
buy 58
buy 93
buy 84
buy 97
buy 85
buy 57
buy 93
buy 95
buy 68
buy 65
buy 67
buy 98
buy 90
buy 86
buy 66
buy 60
buy 84
buy 81
buy 99
buy 57
buy 89
buy 98
buy 99
buy 67
buy 89
buy 77
buy 71
buy 79
buy 93
buy 73
buy 67
buy 90
buy 84
buy 58
buy 60
buy 71
buy 61
buy 66
buy 66
buy 71
buy 56
buy 75
buy 76
buy 98
buy 70
buy 63
buy 94
buy 98
buy 65
buy 87
buy 79
buy 55
buy 94
buy 59
buy 52
buy 53
buy 90
buy 64
buy 60
buy 76
buy 78
buy 73
buy 67
buy 77
buy 50
buy 90
buy 90
buy 52
buy 96
buy 61
buy 92
buy 88
buy 70
buy 70
buy 86
buy 92
buy 75
buy 96
buy 66
buy 81
buy 55
buy 55
buy 79
buy 64
buy 63
buy 86
buy 55
buy 97
buy 66
buy 61
buy 97
buy 76
buy 88
buy 72
buy 81
buy 78
buy 58
buy 83
buy 53
buy 62
buy 69
buy 67
buy 91
buy 72
buy 90
buy 66
buy 80
buy 66
buy 98
buy 58
buy 95
buy 76
buy 79
buy 69
buy 94
buy 76
buy 60
buy 73
buy 96
buy 73
buy 64
buy 98
buy 73
buy 69
buy 81
buy 60
buy 53
buy 50
buy 87
buy 52
buy 77
buy 88
buy 78
buy 73
buy 67
buy 92
buy 57
buy 67
buy 55
buy 91
buy 90
buy 78
buy 69
buy 75
buy 80
buy 92
buy 56
buy 88
buy 69
buy 77
buy 73
buy 61
buy 100
buy 88
buy 87
buy 51
buy 54
buy 76
buy 55
buy 91
buy 91
buy 89
buy 98
buy 50
buy 82
buy 61
buy 51
buy 87
buy 59
buy 88
buy 66
buy 75
buy 65
buy 83
buy 56
buy 58
buy 83
buy 78
buy 100
buy 98
buy 81
buy 64
buy 71
buy 75
buy 54
buy 64
buy 50
buy 84
buy 86
buy 89
buy 65
buy 89
buy 73
buy 83
buy 85
buy 91
buy 53
buy 60
buy 93
buy 55
buy 53
buy 51
buy 51
buy 86
buy 87
buy 98
buy 90
buy 82
buy 81
buy 59
buy 52
buy 69
buy 67
buy 74
buy 77
buy 60
buy 73
buy 70
buy 77
buy 55
buy 91
buy 53
buy 85
buy 83
buy 61
buy 95
buy 58
buy 76
buy 74
buy 100
buy 80
buy 64
buy 84
buy 79
buy 81
buy 69
buy 88
buy 55
buy 64
buy 60
buy 65
buy 60
buy 76
buy 79
buy 91
buy 80
buy 73
buy 69
buy 56
buy 68
buy 62
buy 56
buy 87
buy 53
buy 60
buy 93
buy 98
buy 82
buy 86
buy 80
buy 69
buy 56
buy 93
buy 64
buy 85
buy 86
buy 51
buy 82
buy 55
buy 83
buy 91
