experimentalAnalysis/hash_rb_Experimental/test-f1-4.txt
400000
buy 72
buy 84
buy 94
buy 69
buy 78
buy 58
buy 93
buy 81
buy 97
buy 77
buy 50
buy 69
buy 59
buy 76
buy 88
buy 77
buy 89
buy 68
buy 97
buy 67
buy 65
buy 78
buy 88
buy 51
buy 55
buy 86
buy 68
buy 99
buy 96
buy 89
buy 78
buy 99
buy 71
buy 51
buy 70
buy 93
buy 86
buy 55
buy 60
buy 65
buy 60
buy 71
buy 57
buy 90
buy 60
buy 60
buy 63
buy 79
buy 85
buy 56
buy 54
buy 59
buy 92
buy 72
buy 76
buy 89
buy 56
buy 97
buy 79
buy 92
buy 83
buy 71
buy 93
buy 52
buy 73
buy 69
buy 65
buy 64
buy 92
buy 74
buy 50
buy 89
buy 50
buy 52
buy 56
buy 52
buy 67
buy 97
buy 72
buy 96
buy 100
buy 51
buy 70
buy 100
buy 52
buy 75
buy 53
buy 71
buy 85
buy 82
buy 92
buy 83
buy 88
buy 68
buy 56
buy 89
buy 96
buy 83
buy 65
buy 73
buy 55
buy 88
buy 91
buy 67
buy 58
buy 53
buy 66
buy 79
buy 74
buy 82
buy 98
buy 98
buy 60
buy 87
buy 54
buy 82
buy 92
buy 80
buy 54
buy 81
buy 95
buy 64
buy 95
buy 57
buy 98
buy 82
buy 51
buy 62
buy 70
buy 95
buy 66
buy 80
buy 89
buy 90
buy 85
buy 61
buy 65
buy 53
buy 99
buy 90
buy 78
buy 56
buy 80
buy 72
buy 89
buy 88
buy 61
buy 55
buy 58
buy 93
buy 60
buy 88
buy 87
buy 79
buy 77
buy 62
buy 95
buy 90
buy 84
buy 94
buy 52
buy 99
buy 75
buy 81
buy 95
buy 64
buy 74
buy 92
buy 81
buy 71
buy 63
buy 84
buy 51
buy 68
buy 54
buy 99
buy 55
buy 76
buy 82
buy 64
buy 86
buy 70
buy 60
buy 54
buy 78
buy 94
buy 89
buy 75
buy 69
buy 84
buy 62
buy 79
buy 56
buy 82
buy 56
buy 77
buy 77
buy 92
buy 70
buy 77
buy 71
buy 95
buy 72
buy 64
buy 77
buy 71
buy 70
buy 75
buy 80
buy 52
buy 51
buy 50
buy 52
buy 94
buy 51
buy 58
buy 72
buy 88
buy 96
buy 98
buy 92
buy 68
buy 78
buy 68
buy 55
buy 71
buy 57
buy 85
buy 64
buy 56
buy 88
buy 59
buy 70
buy 89
buy 64
buy 65
buy 73
buy 72
buy 79
buy 71
buy 90
buy 84
buy 90
buy 84
buy 98
buy 86
buy 98
buy 90
buy 100
buy 56
buy 84
buy 78
buy 87
buy 96
buy 99
buy 77
buy 97
buy 74
buy 56
buy 54
buy 52
buy 91
buy 55
buy 84
buy 86
buy 84
buy 52
buy 82
buy 89
buy 53
buy 66
buy 96
buy 70
buy 70
buy 88
buy 72
buy 66
buy 93
buy 61
buy 93
buy 61
buy 77
buy 69
buy 73
buy 91
buy 95
buy 95
buy 92
buy 99
buy 76
buy 75
buy 58
buy 98
buy 65
buy 79
buy 93
buy 53
buy 66
buy 94
buy 63
buy 77
buy 63
buy 81
buy 76
buy 94
buy 54
buy 50
buy 51
buy 68
buy 78
buy 62
buy 70
buy 67
buy 98
buy 83
buy 51
buy 74
buy 68
buy 50
buy 95
buy 57
buy 85
buy 53
buy 95
buy 66
buy 100
buy 56
buy 88
buy 89
buy 98
buy 84
buy 78
buy 58
buy 95
buy 68
buy 62
buy 82
buy 79
buy 51
buy 81
buy 74
buy 56
buy 82
buy 89
buy 54
buy 100
buy 71
buy 58
buy 61
buy 58
buy 78
buy 82
buy 90
buy 86
buy 66
buy 99
buy 62
buy 100
buy 57
buy 74
buy 60
buy 69
buy 67
buy 55
buy 78
buy 73
buy 98
buy 75
buy 91
buy 88
buy 50
buy 99
buy 56
buy 70
buy 75
buy 53
buy 93
buy 70
buy 65
buy 79
buy 60
buy 67
buy 59
buy 55
buy 92
buy 83
buy 58
buy 68
buy 70
buy 91
buy 82
buy 76
buy 98
buy 70
buy 100
buy 98
buy 88
buy 90
buy 100
buy 67
buy 83
buy 65
buy 94
buy 95
buy 77
buy 80
buy 52
buy 86
buy 99
buy 62
buy 58
buy 97
buy 51
buy 70
buy 67
buy 67
buy 99
buy 86
buy 84
buy 84
buy 73
buy 79
buy 62
buy 66
buy 67
buy 57
buy 89
buy 56
buy 84
buy 97
buy 55
buy 53
buy 51
buy 98
buy 68
buy 98
buy 86
buy 70
buy 98
buy 61
buy 69
buy 91
buy 56
buy 79
buy 67
buy 83
buy 76
buy 94
buy 83
buy 65
buy 56
buy 89
buy 59
buy 68
buy 91
buy 73
buy 63
buy 95
buy 84
buy 78
buy 52
buy 56
buy 83
buy 84
buy 67
buy 72
buy 60
buy 88
buy 83
buy 68
buy 52
buy 84
buy 84
buy 90
buy 60
buy 64
buy 94
buy 80
buy 74
buy 73
buy 96
buy 68
buy 62
buy 92
buy 88
buy 97
buy 65
buy 92
buy 80
buy 98
buy 91
buy 67
buy 90
buy 68
buy 77
buy 50
buy 53
buy 75
buy 78
buy 70
buy 88
buy 79
buy 87
buy 99
buy 83
buy 63
buy 79
buy 60
buy 62
buy 65
buy 68
buy 90
buy 84
buy 59
buy 70
buy 95
buy 63
buy 78
buy 65
buy 70
buy 61
buy 77
buy 82
buy 88
buy 54
buy 83
buy 87
buy 79
buy 54
buy 85
buy 65
buy 50
buy 60
buy 65
buy 62
buy 51
buy 85
buy 86
buy 70
buy 100
buy 84
buy 71
buy 92
buy 78
buy 100
buy 60
buy 58
buy 73
buy 85
buy 73
buy 52
buy 88
buy 59
buy 99
buy 75
buy 55
buy 74
buy 54
buy 63
buy 94
buy 85
buy 51
buy 63
buy 60
buy 76
buy 73
buy 90
buy 82
buy 88
buy 74
buy 98
buy 84
buy 51
buy 85
buy 68
buy 71
buy 71
buy 95
buy 95
buy 73
buy 53
buy 87
buy 74
buy 75
buy 59
buy 86
buy 85
buy 90
buy 63
buy 82
buy 93
buy 50
buy 68
buy 61
buy 93
buy 68
buy 54
buy 73
buy 51
buy 85
buy 74
buy 96
buy 56
buy 85
buy 83
buy 80
buy 67
buy 66
buy 50
buy 89
buy 98
buy 73
buy 80
buy 53
buy 58
buy 51
buy 60
buy 98
buy 85
buy 86
buy 77
buy 50
buy 52
buy 92
buy 53
buy 54
buy 52
buy 70
buy 59
buy 59
buy 63
buy 92
buy 89
buy 54
buy 96
buy 92
buy 74
buy 70
buy 86
buy 54
buy 56
buy 74
buy 77
buy 57
buy 77
buy 53
buy 89
buy 80
buy 88
buy 56
buy 98
buy 67
buy 79
buy 56
buy 62
buy 97
buy 83
buy 58
buy 59
buy 81
buy 89
buy 67
buy 80
buy 84
buy 63
buy 61
buy 83
buy 75
buy 87
buy 91
buy 95
buy 56
buy 74
buy 81
buy 55
buy 82
buy 63
buy 98
buy 71
buy 61
buy 53
buy 91
buy 51
buy 93
buy 92
buy 92
buy 88
buy 72
buy 95
buy 98
buy 55
buy 88
buy 61
buy 67
buy 85
buy 64
buy 80
buy 57
buy 78
buy 81
buy 98
buy 71
buy 71
buy 71
buy 59
buy 74
buy 80
buy 71
buy 89
buy 73
buy 66
buy 88
buy 70
buy 61
buy 67
buy 85
buy 66
buy 90
buy 50
buy 51
buy 69
buy 79
buy 67
buy 61
buy 57
buy 85
buy 80
buy 95
buy 78
buy 68
buy 71
buy 60
buy 77
buy 76
buy 60
buy 84
buy 96
buy 62
buy 72
buy 77
buy 95
buy 80
buy 72
buy 72
buy 84
buy 81
buy 57
buy 61
buy 77
buy 51
buy 87
buy 52
buy 71
buy 72
buy 72
buy 80
buy 69
buy 57
buy 65
buy 72
buy 74
buy 74
buy 55
buy 81
buy 62
buy 58
buy 69
buy 96
buy 96
buy 83
buy 84
buy 55
buy 64
buy 58
buy 55
buy 57
buy 98
buy 98
buy 85
buy 60
buy 52
buy 86
buy 58
buy 62
buy 90
buy 67
buy 53
buy 68
buy 73
buy 99
buy 51
buy 77
buy 72
buy 68
buy 83
buy 81
buy 71
buy 100
buy 91
buy 55
buy 73
buy 60
buy 82
buy 88
buy 94
buy 95
buy 98
buy 67
buy 62
buy 50
buy 57
buy 66
buy 52
buy 60
buy 63
buy 88
buy 90
buy 52
buy 79
buy 94
buy 74
buy 56
buy 88
buy 56
buy 69
buy 89
buy 88
buy 72
buy 91
buy 72
buy 83
buy 88
buy 72
buy 82
buy 63
buy 52
buy 77
buy 82
buy 100
buy 73
buy 84
buy 90
buy 52
buy 73
buy 89
buy 81
buy 71
buy 56
buy 60
buy 83
buy 73
buy 54
buy 88
buy 72
buy 87
buy 76
buy 53
buy 86
buy 62
buy 78
buy 76
buy 73
buy 71
buy 80
buy 77
buy 70
buy 88
buy 97
buy 67
buy 57
buy 91
buy 92
buy 71
buy 65
buy 96
buy 83
buy 79
buy 58
buy 68
buy 56
buy 56
buy 66
buy 61
buy 52
buy 73
buy 77
buy 66
buy 83
buy 61
buy 53
buy 63
buy 63
buy 60
buy 54
buy 86
buy 100
buy 93
buy 74
buy 96
buy 92
buy 66
buy 57
buy 96
buy 76
buy 96
buy 66
buy 100
buy 74
buy 93
buy 83
buy 57
buy 95
buy 68
buy 61
buy 59
buy 53
buy 91
buy 52
buy 83
buy 80
buy 88
buy 91
buy 60
buy 89
buy 99
buy 75
buy 94
buy 73
buy 93
buy 84
buy 60
buy 83
buy 56
buy 56
buy 70
buy 96
buy 92
buy 86
buy 50
buy 97
buy 67
buy 100
buy 75
buy 91
buy 54
buy 65
buy 74
buy 68
buy 51
buy 89
buy 98
buy 86
buy 91
buy 65
buy 75
buy 89
buy 54
buy 75
buy 90
buy 58
buy 50
buy 74
buy 100
buy 75
buy 62
buy 94
buy 55
buy 97
buy 51
buy 51
buy 100
buy 77
buy 92
buy 64
buy 85
buy 55
buy 57
buy 94
buy 71
buy 99
buy 70
buy 91
buy 82
buy 59
buy 84
buy 51
buy 78
buy 54
buy 65
buy 99
buy 65
buy 69
buy 71
buy 66
buy 77
buy 75
buy 77
buy 88
buy 87
buy 92
buy 57
buy 55
buy 75
buy 94
buy 50
buy 61
buy 73
buy 69
buy 87
buy 68
buy 55
buy 88
buy 60
buy 86
buy 94
buy 97
buy 82
buy 92
buy 67
buy 75
buy 91
buy 62
buy 63
buy 55
buy 95
buy 52
buy 64
buy 54
buy 89
buy 69
buy 86
buy 86
buy 79
buy 66
buy 61
buy 98
buy 61
buy 52
buy 54
buy 68
buy 84
buy 75
buy 100
buy 54
buy 67
buy 73
buy 70
buy 63
buy 65
buy 54
buy 83
buy 81
buy 91
buy 95
buy 65
buy 79
buy 78
buy 87
buy 89
buy 69
buy 63
buy 60
buy 56
buy 73
buy 97
buy 77
buy 69
buy 61
buy 79
buy 55
buy 97
buy 55
buy 76
buy 54
buy 53
buy 71
buy 65
buy 56
buy 92
buy 62
buy 54
buy 54
buy 100
buy 91
buy 82
buy 77
buy 58
buy 99
buy 100
buy 57
buy 56
buy 64
buy 63
buy 95
buy 64
buy 97
buy 100
buy 69
buy 71
buy 84
buy 68
buy 78
buy 65
buy 97
buy 80
buy 97
buy 94
buy 74
buy 71
buy 92
buy 89
buy 78
buy 84
buy 59
buy 91
buy 100
buy 68
buy 87
buy 87
buy 97
buy 77
buy 86
buy 97
buy 79
buy 69
buy 53
buy 62
buy 53
buy 73
buy 50
buy 76
buy 67
buy 96
buy 74
buy 65
buy 63
buy 54
buy 94
buy 52
